2020-11-21 17:51:38,391 ERROR: Exception on /auth/register [POST] [in c:\users\fernando\documents\software engineering\project\venv\lib\site-packages\flask\app.py:1891]
Traceback (most recent call last):
  File "c:\users\fernando\documents\software engineering\project\venv\lib\site-packages\sqlalchemy\engine\base.py", line 2336, in _wrap_pool_connect
    return fn()
  File "c:\users\fernando\documents\software engineering\project\venv\lib\site-packages\sqlalchemy\pool\base.py", line 364, in connect
    return _ConnectionFairy._checkout(self)
  File "c:\users\fernando\documents\software engineering\project\venv\lib\site-packages\sqlalchemy\pool\base.py", line 778, in _checkout
    fairy = _ConnectionRecord.checkout(pool)
  File "c:\users\fernando\documents\software engineering\project\venv\lib\site-packages\sqlalchemy\pool\base.py", line 495, in checkout
    rec = pool._do_get()
  File "c:\users\fernando\documents\software engineering\project\venv\lib\site-packages\sqlalchemy\pool\impl.py", line 140, in _do_get
    self._dec_overflow()
  File "c:\users\fernando\documents\software engineering\project\venv\lib\site-packages\sqlalchemy\util\langhelpers.py", line 68, in __exit__
    compat.raise_(
  File "c:\users\fernando\documents\software engineering\project\venv\lib\site-packages\sqlalchemy\util\compat.py", line 182, in raise_
    raise exception
  File "c:\users\fernando\documents\software engineering\project\venv\lib\site-packages\sqlalchemy\pool\impl.py", line 137, in _do_get
    return self._create_connection()
  File "c:\users\fernando\documents\software engineering\project\venv\lib\site-packages\sqlalchemy\pool\base.py", line 309, in _create_connection
    return _ConnectionRecord(self)
  File "c:\users\fernando\documents\software engineering\project\venv\lib\site-packages\sqlalchemy\pool\base.py", line 440, in __init__
    self.__connect(first_connect_check=True)
  File "c:\users\fernando\documents\software engineering\project\venv\lib\site-packages\sqlalchemy\pool\base.py", line 661, in __connect
    pool.logger.debug("Error on connect(): %s", e)
  File "c:\users\fernando\documents\software engineering\project\venv\lib\site-packages\sqlalchemy\util\langhelpers.py", line 68, in __exit__
    compat.raise_(
  File "c:\users\fernando\documents\software engineering\project\venv\lib\site-packages\sqlalchemy\util\compat.py", line 182, in raise_
    raise exception
  File "c:\users\fernando\documents\software engineering\project\venv\lib\site-packages\sqlalchemy\pool\base.py", line 656, in __connect
    connection = pool._invoke_creator(self)
  File "c:\users\fernando\documents\software engineering\project\venv\lib\site-packages\sqlalchemy\engine\strategies.py", line 114, in connect
    return dialect.connect(*cargs, **cparams)
  File "c:\users\fernando\documents\software engineering\project\venv\lib\site-packages\sqlalchemy\engine\default.py", line 493, in connect
    return self.dbapi.connect(*cargs, **cparams)
pyodbc.OperationalError: ('08001', '[08001] [Microsoft][ODBC SQL Server Driver][DBNETLIB]SQL Server does not exist or access denied. (17) (SQLDriverConnect); [08001] [Microsoft][ODBC SQL Server Driver][DBNETLIB]ConnectionOpen (Connect()). (53)')

The above exception was the direct cause of the following exception:

Traceback (most recent call last):
  File "c:\users\fernando\documents\software engineering\project\venv\lib\site-packages\flask\app.py", line 2447, in wsgi_app
    response = self.full_dispatch_request()
  File "c:\users\fernando\documents\software engineering\project\venv\lib\site-packages\flask\app.py", line 1952, in full_dispatch_request
    rv = self.handle_user_exception(e)
  File "c:\users\fernando\documents\software engineering\project\venv\lib\site-packages\flask\app.py", line 1821, in handle_user_exception
    reraise(exc_type, exc_value, tb)
  File "c:\users\fernando\documents\software engineering\project\venv\lib\site-packages\flask\_compat.py", line 39, in reraise
    raise value
  File "c:\users\fernando\documents\software engineering\project\venv\lib\site-packages\flask\app.py", line 1950, in full_dispatch_request
    rv = self.dispatch_request()
  File "c:\users\fernando\documents\software engineering\project\venv\lib\site-packages\flask\app.py", line 1936, in dispatch_request
    return self.view_functions[rule.endpoint](**req.view_args)
  File "C:\Users\Fernando\Documents\Software Engineering\Project\app\auth\routes.py", line 38, in register
    if form.validate_on_submit():
  File "c:\users\fernando\documents\software engineering\project\venv\lib\site-packages\flask_wtf\form.py", line 100, in validate_on_submit
    return self.is_submitted() and self.validate()
  File "c:\users\fernando\documents\software engineering\project\venv\lib\site-packages\wtforms\form.py", line 318, in validate
    return super(Form, self).validate(extra)
  File "c:\users\fernando\documents\software engineering\project\venv\lib\site-packages\wtforms\form.py", line 150, in validate
    if not field.validate(self, extra):
  File "c:\users\fernando\documents\software engineering\project\venv\lib\site-packages\wtforms\fields\core.py", line 226, in validate
    stop_validation = self._run_validation_chain(form, chain)
  File "c:\users\fernando\documents\software engineering\project\venv\lib\site-packages\wtforms\fields\core.py", line 246, in _run_validation_chain
    validator(form, self)
  File "C:\Users\Fernando\Documents\Software Engineering\Project\app\auth\forms.py", line 22, in validate_username
    user = User.query.filter_by(username=username.data).first()
  File "c:\users\fernando\documents\software engineering\project\venv\lib\site-packages\sqlalchemy\orm\query.py", line 3429, in first
    ret = list(self[0:1])
  File "c:\users\fernando\documents\software engineering\project\venv\lib\site-packages\sqlalchemy\orm\query.py", line 3203, in __getitem__
    return list(res)
  File "c:\users\fernando\documents\software engineering\project\venv\lib\site-packages\sqlalchemy\orm\query.py", line 3535, in __iter__
    return self._execute_and_instances(context)
  File "c:\users\fernando\documents\software engineering\project\venv\lib\site-packages\sqlalchemy\orm\query.py", line 3556, in _execute_and_instances
    conn = self._get_bind_args(
  File "c:\users\fernando\documents\software engineering\project\venv\lib\site-packages\sqlalchemy\orm\query.py", line 3571, in _get_bind_args
    return fn(
  File "c:\users\fernando\documents\software engineering\project\venv\lib\site-packages\sqlalchemy\orm\query.py", line 3550, in _connection_from_session
    conn = self.session.connection(**kw)
  File "c:\users\fernando\documents\software engineering\project\venv\lib\site-packages\sqlalchemy\orm\session.py", line 1138, in connection
    return self._connection_for_bind(
  File "c:\users\fernando\documents\software engineering\project\venv\lib\site-packages\sqlalchemy\orm\session.py", line 1146, in _connection_for_bind
    return self.transaction._connection_for_bind(
  File "c:\users\fernando\documents\software engineering\project\venv\lib\site-packages\sqlalchemy\orm\session.py", line 433, in _connection_for_bind
    conn = bind._contextual_connect()
  File "c:\users\fernando\documents\software engineering\project\venv\lib\site-packages\sqlalchemy\engine\base.py", line 2302, in _contextual_connect
    self._wrap_pool_connect(self.pool.connect, None),
  File "c:\users\fernando\documents\software engineering\project\venv\lib\site-packages\sqlalchemy\engine\base.py", line 2339, in _wrap_pool_connect
    Connection._handle_dbapi_exception_noconnection(
  File "c:\users\fernando\documents\software engineering\project\venv\lib\site-packages\sqlalchemy\engine\base.py", line 1583, in _handle_dbapi_exception_noconnection
    util.raise_(
  File "c:\users\fernando\documents\software engineering\project\venv\lib\site-packages\sqlalchemy\util\compat.py", line 182, in raise_
    raise exception
  File "c:\users\fernando\documents\software engineering\project\venv\lib\site-packages\sqlalchemy\engine\base.py", line 2336, in _wrap_pool_connect
    return fn()
  File "c:\users\fernando\documents\software engineering\project\venv\lib\site-packages\sqlalchemy\pool\base.py", line 364, in connect
    return _ConnectionFairy._checkout(self)
  File "c:\users\fernando\documents\software engineering\project\venv\lib\site-packages\sqlalchemy\pool\base.py", line 778, in _checkout
    fairy = _ConnectionRecord.checkout(pool)
  File "c:\users\fernando\documents\software engineering\project\venv\lib\site-packages\sqlalchemy\pool\base.py", line 495, in checkout
    rec = pool._do_get()
  File "c:\users\fernando\documents\software engineering\project\venv\lib\site-packages\sqlalchemy\pool\impl.py", line 140, in _do_get
    self._dec_overflow()
  File "c:\users\fernando\documents\software engineering\project\venv\lib\site-packages\sqlalchemy\util\langhelpers.py", line 68, in __exit__
    compat.raise_(
  File "c:\users\fernando\documents\software engineering\project\venv\lib\site-packages\sqlalchemy\util\compat.py", line 182, in raise_
    raise exception
  File "c:\users\fernando\documents\software engineering\project\venv\lib\site-packages\sqlalchemy\pool\impl.py", line 137, in _do_get
    return self._create_connection()
  File "c:\users\fernando\documents\software engineering\project\venv\lib\site-packages\sqlalchemy\pool\base.py", line 309, in _create_connection
    return _ConnectionRecord(self)
  File "c:\users\fernando\documents\software engineering\project\venv\lib\site-packages\sqlalchemy\pool\base.py", line 440, in __init__
    self.__connect(first_connect_check=True)
  File "c:\users\fernando\documents\software engineering\project\venv\lib\site-packages\sqlalchemy\pool\base.py", line 661, in __connect
    pool.logger.debug("Error on connect(): %s", e)
  File "c:\users\fernando\documents\software engineering\project\venv\lib\site-packages\sqlalchemy\util\langhelpers.py", line 68, in __exit__
    compat.raise_(
  File "c:\users\fernando\documents\software engineering\project\venv\lib\site-packages\sqlalchemy\util\compat.py", line 182, in raise_
    raise exception
  File "c:\users\fernando\documents\software engineering\project\venv\lib\site-packages\sqlalchemy\pool\base.py", line 656, in __connect
    connection = pool._invoke_creator(self)
  File "c:\users\fernando\documents\software engineering\project\venv\lib\site-packages\sqlalchemy\engine\strategies.py", line 114, in connect
    return dialect.connect(*cargs, **cparams)
  File "c:\users\fernando\documents\software engineering\project\venv\lib\site-packages\sqlalchemy\engine\default.py", line 493, in connect
    return self.dbapi.connect(*cargs, **cparams)
sqlalchemy.exc.OperationalError: (pyodbc.OperationalError) ('08001', '[08001] [Microsoft][ODBC SQL Server Driver][DBNETLIB]SQL Server does not exist or access denied. (17) (SQLDriverConnect); [08001] [Microsoft][ODBC SQL Server Driver][DBNETLIB]ConnectionOpen (Connect()). (53)')
(Background on this error at: http://sqlalche.me/e/13/e3q8)
