2020-11-19 21:31:23,734 ERROR: Exception on /index [GET] [in c:\users\fernando\documents\software engineering\project\venv\lib\site-packages\flask\app.py:1891]
Traceback (most recent call last):
  File "c:\users\fernando\documents\software engineering\project\venv\lib\site-packages\flask\app.py", line 2447, in wsgi_app
    response = self.full_dispatch_request()
  File "c:\users\fernando\documents\software engineering\project\venv\lib\site-packages\flask\app.py", line 1952, in full_dispatch_request
    rv = self.handle_user_exception(e)
  File "c:\users\fernando\documents\software engineering\project\venv\lib\site-packages\flask\app.py", line 1821, in handle_user_exception
    reraise(exc_type, exc_value, tb)
  File "c:\users\fernando\documents\software engineering\project\venv\lib\site-packages\flask\_compat.py", line 39, in reraise
    raise value
  File "c:\users\fernando\documents\software engineering\project\venv\lib\site-packages\flask\app.py", line 1950, in full_dispatch_request
    rv = self.dispatch_request()
  File "c:\users\fernando\documents\software engineering\project\venv\lib\site-packages\flask\app.py", line 1936, in dispatch_request
    return self.view_functions[rule.endpoint](**req.view_args)
  File "c:\users\fernando\documents\software engineering\project\venv\lib\site-packages\flask_login\utils.py", line 270, in decorated_view
    elif not current_user.is_authenticated:
  File "c:\users\fernando\documents\software engineering\project\venv\lib\site-packages\werkzeug\local.py", line 347, in __getattr__
    return getattr(self._get_current_object(), name)
  File "c:\users\fernando\documents\software engineering\project\venv\lib\site-packages\werkzeug\local.py", line 306, in _get_current_object
    return self.__local()
  File "c:\users\fernando\documents\software engineering\project\venv\lib\site-packages\flask_login\utils.py", line 26, in <lambda>
    current_user = LocalProxy(lambda: _get_user())
  File "c:\users\fernando\documents\software engineering\project\venv\lib\site-packages\flask_login\utils.py", line 346, in _get_user
    current_app.login_manager._load_user()
  File "c:\users\fernando\documents\software engineering\project\venv\lib\site-packages\flask_login\login_manager.py", line 318, in _load_user
    user = self._user_callback(user_id)
  File "C:\Users\Fernando\Documents\Software Engineering\Project\app\models.py", line 10, in load_user
    return User.query.get(int(id))
  File "c:\users\fernando\documents\software engineering\project\venv\lib\site-packages\flask_sqlalchemy\__init__.py", line 512, in __get__
    mapper = orm.class_mapper(type)
  File "c:\users\fernando\documents\software engineering\project\venv\lib\site-packages\sqlalchemy\orm\base.py", line 451, in class_mapper
    mapper = _inspect_mapped_class(class_, configure=configure)
  File "c:\users\fernando\documents\software engineering\project\venv\lib\site-packages\sqlalchemy\orm\base.py", line 430, in _inspect_mapped_class
    mapper._configure_all()
  File "c:\users\fernando\documents\software engineering\project\venv\lib\site-packages\sqlalchemy\orm\mapper.py", line 1352, in _configure_all
    configure_mappers()
  File "c:\users\fernando\documents\software engineering\project\venv\lib\site-packages\sqlalchemy\orm\mapper.py", line 3295, in configure_mappers
    raise e
sqlalchemy.exc.InvalidRequestError: One or more mappers failed to initialize - can't proceed with initialization of other mappers. Triggering mapper: 'mapped class Device->deviceTable'. Original exception was: Could not determine join condition between parent/child tables on relationship Device.unlocks - there are no foreign keys linking these tables.  Ensure that referencing columns are associated with a ForeignKey or ForeignKeyConstraint, or specify a 'primaryjoin' expression.
2020-11-19 21:31:28,578 INFO: LogView startup [in C:\Users\Fernando\Documents\Software Engineering\Project\app\__init__.py:51]
